在 JavaScript 中，使用 `async/await` 处理异步操作时，可以通过 `try...catch` 语句来捕获异常。下面是如何使用 `async/await` 捕获异常的详细说明。

### 基本用法

1. **使用 `try...catch`**：
   - 将 `await` 放在 `try` 块中，并在 `catch` 块中处理可能抛出的错误。

#### 示例

```javascript
async function fetchData() {
  try {
    const response = await fetch('https://api.example.com/data'); // 假设这个请求可能会失败
    if (!response.ok) {
      throw new Error('Network response was not ok'); // 手动抛出错误
    }
    const data = await response.json();
    console.log(data);
  } catch (error) {
    console.error('Error fetching data:', error); // 捕获并处理错误
  }
}

fetchData();
```

### 捕获多个异常

可以在 `try` 块中执行多个 `await` 操作，只要在 `catch` 块中处理异常即可。

```javascript
async function processData() {
  try {
    const data1 = await fetchData1(); // 可能抛出错误
    const data2 = await fetchData2(); // 可能抛出错误
    // 处理 data1 和 data2
  } catch (error) {
    console.error('Error processing data:', error); // 捕获任何一个异步操作的错误
  }
}

processData();
```

### 捕获 Promise 相关错误

- `await` 后面的 Promise 如果被拒绝（rejected），则会抛出一个异常，因此 `try...catch` 也可以捕获到这些错误。
- 注意，只有在 `await` 语句中直接处理的 Promise 抛出的异常才会被捕获。如果 Promise 在外部被处理，`catch` 语句不会捕获这些错误。

### 总结

使用 `async/await` 时，捕获异常的最佳实践是将 `await` 放在 `try` 块中，并在 `catch` 块中处理异常。这使得异步代码的错误处理变得更加直观和易于管理。这种方式提供了一种清晰的结构，有助于提高代码的可读性和可维护性。