要为自定义的 `Promise` 实现补充 `catch` 和 `finally` 方法。以下是这两个方法的作用和实现方式：

- **`catch` 方法**：用于捕获 `Promise` 链中的错误，相当于 `.then(null, onRejected)`，简化了错误处理。
- **`finally` 方法**：无论 `Promise` 是 `fulfilled` 还是 `rejected`，都执行指定的回调，类似于 `try...finally` 的作用。它并不会更改原有的状态和结果，而是在回调后将值传递给下一个 `then`。

### 实现 `catch` 和 `finally`

在我们的 `MyPromise` 类中添加 `catch` 和 `finally` 方法：

```javascript
class MyPromise {
  constructor(executor) {
    this.state = 'pending';
    this.value = undefined;
    this.callbacks = [];

    const resolve = (value) => {
      if (this.state === 'pending') {
        this.state = 'fulfilled';
        this.value = value;
        this.callbacks.forEach(callback => this.handleCallback(callback));
      }
    };

    const reject = (reason) => {
      if (this.state === 'pending') {
        this.state = 'rejected';
        this.value = reason;
        this.callbacks.forEach(callback => this.handleCallback(callback));
      }
    };

    try {
      executor(resolve, reject);
    } catch (error) {
      reject(error);
    }
  }

  handleCallback(callback) {
    if (this.state === 'fulfilled') {
      setTimeout(() => callback.onFulfilled(this.value), 0);
    } else if (this.state === 'rejected') {
      setTimeout(() => callback.onRejected(this.value), 0);
    }
  }

  then(onFulfilled, onRejected) {
    return new MyPromise((resolve, reject) => {
      const callback = {
        onFulfilled: (value) => {
          try {
            if (typeof onFulfilled === 'function') {
              const result = onFulfilled(value);
              result instanceof MyPromise ? result.then(resolve, reject) : resolve(result);
            } else {
              resolve(value);
            }
          } catch (error) {
            reject(error);
          }
        },
        onRejected: (reason) => {
          try {
            if (typeof onRejected === 'function') {
              const result = onRejected(reason);
              result instanceof MyPromise ? result.then(resolve, reject) : reject(result);
            } else {
              reject(reason);
            }
          } catch (error) {
            reject(error);
          }
        }
      };

      if (this.state === 'pending') {
        this.callbacks.push(callback);
      } else {
        this.handleCallback(callback);
      }
    });
  }

  // 添加 catch 方法
  catch(onRejected) {
    return this.then(null, onRejected);
  }

  // 添加 finally 方法
  finally(callback) {
    return this.then(
      (value) => {
        return MyPromise.resolve(callback()).then(() => value);
      },
      (reason) => {
        return MyPromise.resolve(callback()).then(() => { throw reason });
      }
    );
  }

  // 静态 resolve 方法
  static resolve(value) {
    return new MyPromise((resolve) => resolve(value));
  }

  // 静态 reject 方法
  static reject(reason) {
    return new MyPromise((_, reject) => reject(reason));
  }
}
```

### 使用示例

```javascript
const promise = new MyPromise((resolve, reject) => {
  setTimeout(() => reject('Error occurred'), 1000);
});

promise
  .then((value) => {
    console.log('Fulfilled with:', value);
    return 'Another success';
  })
  .catch((error) => {
    console.error('Caught error:', error);
  })
  .finally(() => {
    console.log('Finally block executed');
  });
```

### 解释

1. **`catch`**：是 `then` 的简化版，专用于错误处理，相当于 `.then(null, onRejected)`，它直接调用 `then` 并只传入 `onRejected`。
2. **`finally`**：无论 `fulfilled` 或 `rejected` 状态都会执行回调，且不会更改 `Promise` 的状态。回调执行后会将初始 `value` 或 `reason` 传递给下一个链。

### 总结

这样实现的 `catch` 和 `finally` 为自定义 `Promise` 增加了更方便的错误捕获和清理机制，使得 `Promise` 链更加完整。